/usr/bin/python3: can't open file '/media/utsav/77f97bd8-cb4e-4891-9e00-a700efef6596/pythonapp-supervisor/app.py': [Errno 2] No such file or directory
/usr/bin/python3: can't open file '/media/utsav/77f97bd8-cb4e-4891-9e00-a700efef6596/pythonapp-supervisor/app.py': [Errno 2] No such file or directory
/usr/bin/python3: can't open file '/media/utsav/77f97bd8-cb4e-4891-9e00-a700efef6596/pythonapp-supervisor/app.py': [Errno 2] No such file or directory
/usr/bin/python3: can't open file '/media/utsav/77f97bd8-cb4e-4891-9e00-a700efef6596/pythonapp-supervisor/app.py': [Errno 2] No such file or directory
/usr/bin/python3: can't open file '/media/utsav/77f97bd8-cb4e-4891-9e00-a700efef6596/pythonapp-supervisor/app.py': [Errno 2] No such file or directory
/usr/bin/python3: can't open file '/media/utsav/77f97bd8-cb4e-4891-9e00-a700efef6596/pythonapp-supervisor/app.py': [Errno 2] No such file or directory
/usr/bin/python3: can't open file '/media/utsav/77f97bd8-cb4e-4891-9e00-a700efef6596/pythonapp-supervisor/app.py': [Errno 2] No such file or directory
/usr/bin/python3: can't open file '/media/utsav/77f97bd8-cb4e-4891-9e00-a700efef6596/pythonapp-supervisor/app.py': [Errno 2] No such file or directory
/usr/bin/python3: can't open file '/media/utsav/77f97bd8-cb4e-4891-9e00-a700efef6596/pythonapp-supervisor/app.py': [Errno 2] No such file or directory
/usr/bin/python3: can't open file '/media/utsav/77f97bd8-cb4e-4891-9e00-a700efef6596/pythonapp-supervisor/app.py': [Errno 2] No such file or directory
/usr/bin/python3: can't open file '/media/utsav/77f97bd8-cb4e-4891-9e00-a700efef6596/pythonapp-supervisor/app.py': [Errno 2] No such file or directory
/usr/bin/python3: can't open file '/media/utsav/77f97bd8-cb4e-4891-9e00-a700efef6596/pythonapp-supervisor/app.py': [Errno 2] No such file or directory
Traceback (most recent call last):
  File "/media/utsav/77f97bd8-cb4e-4891-9e00-a700efef6596/pythonapp-supervisor/app1.py", line 15, in <module>
    main()
  File "/media/utsav/77f97bd8-cb4e-4891-9e00-a700efef6596/pythonapp-supervisor/app1.py", line 10, in main
    raise Exception('custom exception')
Exception: custom exception
Traceback (most recent call last):
  File "/media/utsav/77f97bd8-cb4e-4891-9e00-a700efef6596/pythonapp-supervisor/app1.py", line 15, in <module>
    main()
  File "/media/utsav/77f97bd8-cb4e-4891-9e00-a700efef6596/pythonapp-supervisor/app1.py", line 10, in main
    raise Exception('custom exception')
Exception: custom exception
Traceback (most recent call last):
  File "/media/utsav/77f97bd8-cb4e-4891-9e00-a700efef6596/pythonapp-supervisor/app1.py", line 15, in <module>
    main()
  File "/media/utsav/77f97bd8-cb4e-4891-9e00-a700efef6596/pythonapp-supervisor/app1.py", line 10, in main
    raise Exception('custom exception')
Exception: custom exception
Traceback (most recent call last):
  File "/media/utsav/77f97bd8-cb4e-4891-9e00-a700efef6596/pythonapp-supervisor/app1.py", line 15, in <module>
    main()
  File "/media/utsav/77f97bd8-cb4e-4891-9e00-a700efef6596/pythonapp-supervisor/app1.py", line 10, in main
    #     raise Exception('custom exception')
Exception: custom exception
